
The following have been reloaded with a version change:
  1) anaconda/3-5.1 => anaconda/3-4.2.0

python: can't open file '../run_gpr/run_glac1d_l71C_p2_3_5010_3990': [Errno 2] No such file or directory
