2020-02-21 00:13:32.040234: W tensorflow/stream_executor/platform/default/dso_loader.cc:55] Could not load dynamic library 'libnvinfer.so.6'; dlerror: libnvinfer.so.6: cannot open shared object file: No such file or directory; LD_LIBRARY_PATH: /cm/shared/apps/slurm/17.11.2/lib64/slurm:/cm/shared/apps/slurm/17.11.2/lib64:/cm/local/apps/gcc/6.1.0/lib:/cm/local/apps/gcc/6.1.0/lib64
2020-02-21 00:13:32.040677: W tensorflow/stream_executor/platform/default/dso_loader.cc:55] Could not load dynamic library 'libnvinfer_plugin.so.6'; dlerror: libnvinfer_plugin.so.6: cannot open shared object file: No such file or directory; LD_LIBRARY_PATH: /cm/shared/apps/slurm/17.11.2/lib64/slurm:/cm/shared/apps/slurm/17.11.2/lib64:/cm/local/apps/gcc/6.1.0/lib:/cm/local/apps/gcc/6.1.0/lib64
2020-02-21 00:13:32.040720: W tensorflow/compiler/tf2tensorrt/utils/py_utils.cc:30] Cannot dlopen some TensorRT libraries. If you would like to use Nvidia GPU with TensorRT, please make sure the missing libraries mentioned above are installed properly.
2020-02-21 00:16:18.095270: W tensorflow/stream_executor/platform/default/dso_loader.cc:55] Could not load dynamic library 'libcuda.so.1'; dlerror: libcuda.so.1: cannot open shared object file: No such file or directory; LD_LIBRARY_PATH: /cm/shared/apps/slurm/17.11.2/lib64/slurm:/cm/shared/apps/slurm/17.11.2/lib64:/cm/local/apps/gcc/6.1.0/lib:/cm/local/apps/gcc/6.1.0/lib64
2020-02-21 00:16:18.095375: E tensorflow/stream_executor/cuda/cuda_driver.cc:351] failed call to cuInit: UNKNOWN ERROR (303)
2020-02-21 00:16:18.095449: I tensorflow/stream_executor/cuda/cuda_diagnostics.cc:156] kernel driver does not appear to be running on this host (node248): /proc/driver/nvidia/version does not exist
2020-02-21 00:16:18.097163: I tensorflow/core/platform/cpu_feature_guard.cc:142] Your CPU supports instructions that this TensorFlow binary was not compiled to use: AVX2 FMA
2020-02-21 00:16:18.388823: I tensorflow/core/platform/profile_utils/cpu_utils.cc:94] CPU Frequency: 2194770000 Hz
2020-02-21 00:16:18.419073: I tensorflow/compiler/xla/service/service.cc:168] XLA service 0x55555d523a00 initialized for platform Host (this does not guarantee that XLA will be used). Devices:
2020-02-21 00:16:18.419135: I tensorflow/compiler/xla/service/service.cc:176]   StreamExecutor device (0): Host, Default Version
WARNING:tensorflow:From readv_it.py:469: AffineScalar.__init__ (from tensorflow_probability.python.bijectors.affine_scalar) is deprecated and will be removed after 2020-01-01.
Instructions for updating:
`AffineScalar` bijector is deprecated; please use `tfb.Shift(loc)(tfb.Scale(...))` instead.
2020-02-21 00:16:19.585229: W tensorflow/python/util/util.cc:319] Sets are not currently considered sequences, but this may change in the future, so consider avoiding using them.
Traceback (most recent call last):
  File "/rigel/home/rcc2167/.conda/envs/gpflow6_0/lib/python3.6/runpy.py", line 193, in _run_module_as_main
    "__main__", mod_spec)
  File "/rigel/home/rcc2167/.conda/envs/gpflow6_0/lib/python3.6/runpy.py", line 85, in _run_code
    exec(code, run_globals)
  File "/rigel/home/rcc2167/.conda/envs/gpflow6_0/lib/python3.6/site-packages/memory_profiler.py", line 1274, in <module>
    exec_with_profiler(script_filename, prof, args.backend, script_args)
  File "/rigel/home/rcc2167/.conda/envs/gpflow6_0/lib/python3.6/site-packages/memory_profiler.py", line 1175, in exec_with_profiler
    exec(compile(f.read(), filename, 'exec'), ns, ns)
  File "readv_it.py", line 1071, in <module>
    readv()
  File "/rigel/home/rcc2167/.conda/envs/gpflow6_0/lib/python3.6/site-packages/memory_profiler.py", line 1113, in wrapper
    val = prof(func)(*args, **kwargs)
  File "/rigel/home/rcc2167/.conda/envs/gpflow6_0/lib/python3.6/site-packages/memory_profiler.py", line 699, in f
    return func(*args, **kwds)
  File "readv_it.py", line 840, in readv
    df_nufsamps = locs_with_enoughsamples(df_place, place, number)
  File "readv_it.py", line 834, in locs_with_enoughsamples
    df_locs = pd.concat(df_locs)
  File "/rigel/home/rcc2167/.local/lib/python3.6/site-packages/pandas/core/reshape/concat.py", line 255, in concat
    sort=sort,
  File "/rigel/home/rcc2167/.local/lib/python3.6/site-packages/pandas/core/reshape/concat.py", line 304, in __init__
    raise ValueError("No objects to concatenate")
ValueError: No objects to concatenate
---------------
glac1d_l71C_ump2_lm3 run number 0
number of datapoints =  (230, 8)
model built, time= 1.4874675273895264
model minimized, time= 20.865604639053345
time elapsed =  24.745824337005615
negative log marginal likelihood = -132.63385213280162
