2020-02-21 01:06:52.199827: W tensorflow/stream_executor/platform/default/dso_loader.cc:55] Could not load dynamic library 'libnvinfer.so.6'; dlerror: libnvinfer.so.6: cannot open shared object file: No such file or directory; LD_LIBRARY_PATH: /cm/shared/apps/slurm/17.11.2/lib64/slurm:/cm/shared/apps/slurm/17.11.2/lib64:/cm/local/apps/gcc/6.1.0/lib:/cm/local/apps/gcc/6.1.0/lib64
2020-02-21 01:06:52.200456: W tensorflow/stream_executor/platform/default/dso_loader.cc:55] Could not load dynamic library 'libnvinfer_plugin.so.6'; dlerror: libnvinfer_plugin.so.6: cannot open shared object file: No such file or directory; LD_LIBRARY_PATH: /cm/shared/apps/slurm/17.11.2/lib64/slurm:/cm/shared/apps/slurm/17.11.2/lib64:/cm/local/apps/gcc/6.1.0/lib:/cm/local/apps/gcc/6.1.0/lib64
2020-02-21 01:06:52.200491: W tensorflow/compiler/tf2tensorrt/utils/py_utils.cc:30] Cannot dlopen some TensorRT libraries. If you would like to use Nvidia GPU with TensorRT, please make sure the missing libraries mentioned above are installed properly.
2020-02-21 01:12:10.924322: W tensorflow/stream_executor/platform/default/dso_loader.cc:55] Could not load dynamic library 'libcuda.so.1'; dlerror: libcuda.so.1: cannot open shared object file: No such file or directory; LD_LIBRARY_PATH: /cm/shared/apps/slurm/17.11.2/lib64/slurm:/cm/shared/apps/slurm/17.11.2/lib64:/cm/local/apps/gcc/6.1.0/lib:/cm/local/apps/gcc/6.1.0/lib64
2020-02-21 01:12:10.924419: E tensorflow/stream_executor/cuda/cuda_driver.cc:351] failed call to cuInit: UNKNOWN ERROR (303)
2020-02-21 01:12:10.924468: I tensorflow/stream_executor/cuda/cuda_diagnostics.cc:156] kernel driver does not appear to be running on this host (node065): /proc/driver/nvidia/version does not exist
2020-02-21 01:12:10.925393: I tensorflow/core/platform/cpu_feature_guard.cc:142] Your CPU supports instructions that this TensorFlow binary was not compiled to use: AVX2 FMA
2020-02-21 01:12:10.933713: I tensorflow/core/platform/profile_utils/cpu_utils.cc:94] CPU Frequency: 2194870000 Hz
2020-02-21 01:12:10.942015: I tensorflow/compiler/xla/service/service.cc:168] XLA service 0x55555d02cca0 initialized for platform Host (this does not guarantee that XLA will be used). Devices:
2020-02-21 01:12:10.942048: I tensorflow/compiler/xla/service/service.cc:176]   StreamExecutor device (0): Host, Default Version
WARNING:tensorflow:From readv_it.py:469: AffineScalar.__init__ (from tensorflow_probability.python.bijectors.affine_scalar) is deprecated and will be removed after 2020-01-01.
Instructions for updating:
`AffineScalar` bijector is deprecated; please use `tfb.Shift(loc)(tfb.Scale(...))` instead.
2020-02-21 01:12:11.188126: W tensorflow/python/util/util.cc:319] Sets are not currently considered sequences, but this may change in the future, so consider avoiding using them.
readv_it.py:709: RuntimeWarning: More than 20 figures have been opened. Figures created through the pyplot interface (`matplotlib.pyplot.figure`) are retained until explicitly closed and may consume too much memory. (To control this warning, see the rcParam `figure.max_open_warning`).
  subplot_kw=dict(projection=projection))
readv_it.py:853: RuntimeWarning: More than 20 figures have been opened. Figures created through the pyplot interface (`matplotlib.pyplot.figure`) are retained until explicitly closed and may consume too much memory. (To control this warning, see the rcParam `figure.max_open_warning`).
  fig, ax = plt.subplots(2, len(df_nufsamps.locnum.unique()), figsize=(18, 8))
readv_it.py:907: RuntimeWarning: More than 20 figures have been opened. Figures created through the pyplot interface (`matplotlib.pyplot.figure`) are retained until explicitly closed and may consume too much memory. (To control this warning, see the rcParam `figure.max_open_warning`).
  figsize=(18, 4), subplot_kw=dict(projection=projection))
Traceback (most recent call last):
  File "/rigel/home/rcc2167/.conda/envs/gpflow6_0/lib/python3.6/runpy.py", line 193, in _run_module_as_main
    "__main__", mod_spec)
  File "/rigel/home/rcc2167/.conda/envs/gpflow6_0/lib/python3.6/runpy.py", line 85, in _run_code
    exec(code, run_globals)
  File "/rigel/home/rcc2167/.conda/envs/gpflow6_0/lib/python3.6/site-packages/memory_profiler.py", line 1274, in <module>
    exec_with_profiler(script_filename, prof, args.backend, script_args)
  File "/rigel/home/rcc2167/.conda/envs/gpflow6_0/lib/python3.6/site-packages/memory_profiler.py", line 1175, in exec_with_profiler
    exec(compile(f.read(), filename, 'exec'), ns, ns)
  File "readv_it.py", line 1063, in <module>
    readv()
  File "/rigel/home/rcc2167/.conda/envs/gpflow6_0/lib/python3.6/site-packages/memory_profiler.py", line 1113, in wrapper
    val = prof(func)(*args, **kwargs)
  File "/rigel/home/rcc2167/.conda/envs/gpflow6_0/lib/python3.6/site-packages/memory_profiler.py", line 699, in f
    return func(*args, **kwds)
  File "readv_it.py", line 983, in readv
    da_A1 = make_dataarray(A1)
  File "readv_it.py", line 971, in make_dataarray
    coords = [lon, lat, ages]
NameError: name 'lon' is not defined
---------------
glac1d_l71C_ump2_lm20 run number 0
number of datapoints =  (1794, 8)
model built, time= 0.2490215301513672
model minimized, time= 9412.548514604568
time elapsed =  9672.181804418564
negative log marginal likelihood = -1362.0659069200478
